<?xml version="1.0" ?>
<!-- =================================================================================== -->
<!-- |    This document was autogenerated by xacro from mini.xacro                     | -->
<!-- |    EDITING THIS FILE BY HAND IS NOT RECOMMENDED                                 | -->
<!-- =================================================================================== -->
<robot name="scout_mini">
  <link name="base_link">
    <inertial>
      <origin xyz="0.0 0.0 0.0" rpy="0.0 0.0 0.0"/>
      <mass value="17"/>
      <inertia ixx="0.1859" ixy="0.0" ixz="0.0" iyy="0.4012" iyz="0.0" izz="0.5273"/>      </inertial>
    <visual>
      <origin rpy="1.57 0 -1.57" xyz="0 0 0.0"/>
      <geometry>
        <mesh filename="package://scout_description/meshes/scout_mini_base_link2.dae"/>
      </geometry>
    </visual>
    <collision>
      <origin rpy="0 0 0" xyz="0 0 0"/>
      <geometry>
        <!-- <mesh filename="package://scout_description/meshes/scout_mini_base_link2.dae"/> -->
        <box size="0.512 0.332 0.145"/>
      </geometry>
    </collision>
  </link>
  <link name="front_left_wheel_link">
    <inertial>
      <mass value="1.5"/>
      <origin xyz="0 0 0"/>
      <inertia ixx="0.0032" ixy="0.0" ixz="0.0" iyy="0.0032" iyz="0.0" izz="0.0048"/>
    </inertial>
    <visual>
      <origin rpy="0 0 0" xyz="0 0 0"/>
      <geometry>
        <mesh filename="package://scout_description/meshes/wheel.dae"/>
      </geometry>
    </visual>
    <collision>
      <origin rpy="0 0 0" xyz="0 0 0.03"/>
      <geometry>
        <!-- <mesh filename="package://scout_description/meshes/wheel.dae"/> -->
        <cylinder radius="0.08" length="0.08"/>
      </geometry>
    </collision>
  </link>
  <joint name="front_left_wheel" type="continuous">

    <parent link="base_link"/>
    <child link="front_left_wheel_link"/>
    <origin rpy="-1.57 0 0" xyz="0.2319755 0.2082515 -0.100998"/>
    <axis rpy="0 0 0" xyz="0 0 1"/>
  </joint>
  <link name="rear_left_wheel_link">

    <inertial>
      <mass value="1.5"/>
      <origin xyz="0 0 0"/>
      <inertia ixx="0.0032" ixy="0.0" ixz="0.0" iyy="0.0032" iyz="0.0" izz="0.0048"/>
    </inertial>
    <visual>
      <origin rpy="0 0 0" xyz="0 0 0"/>
      <geometry>
        <mesh filename="package://scout_description/meshes/wheel.dae"/>
      </geometry>
    </visual>
    <collision>
      <origin rpy="0 0 0" xyz="0 0 0"/>
      <geometry>
        <!-- <mesh filename="package://scout_description/meshes/wheel.dae"/> -->
        <cylinder radius="0.08" length="0.08"/>
      </geometry>
    </collision>
  </link>
  <joint name="rear_left_wheel" type="continuous">

    <parent link="base_link"/>
    <child link="rear_left_wheel_link"/>
    <origin rpy="-1.57 0 0" xyz="-0.2319755 0.2082515 -0.100998"/>
    <axis rpy="0 0 0" xyz="0 0 1"/>
  </joint>
  <link name="front_right_wheel_link">
    <inertial>
      <mass value="1.5"/>
      <origin xyz="0 0 0"/>
      <inertia ixx="0.0032" ixy="0.0" ixz="0.0" iyy="0.0032" iyz="0.0" izz="0.0048"/>
    </inertial>
    <visual>
      <origin rpy="0 0 0" xyz="0 0 0"/>
      <geometry>
        <mesh filename="package://scout_description/meshes/wheel.dae"/>
      </geometry>
    </visual>
    <collision>
      <origin rpy="0 0 0" xyz="0 0 0"/>
      <geometry>
        <!-- <mesh filename="package://scout_description/meshes/wheel.dae"/> -->
        <cylinder radius="0.08" length="0.08"/>

      </geometry>
    </collision>
  </link>
  <joint name="front_right_wheel" type="continuous">

    <parent link="base_link"/>
    <child link="front_right_wheel_link"/>
    <origin rpy="1.57 0 0" xyz="0.2319755 -0.2082515 -0.099998"/>
    <axis rpy="0 0 0" xyz="0 0 -1"/>
  </joint>
  <link name="rear_right_wheel_link">

    <inertial>
      <mass value="1.5"/>
      <origin xyz="0 0 0"/>
      <inertia ixx="0.0032" ixy="0.0" ixz="0.0" iyy="0.0032" iyz="0.0" izz="0.0048"/>
    </inertial>
    <visual>
      <origin rpy="0 0 0" xyz="0 0 0"/>
      <geometry>
        <mesh filename="package://scout_description/meshes/wheel.dae"/>
      </geometry>
    </visual>
    <collision>
      <origin rpy="0 0 0" xyz="0 0 0"/>
      <geometry>
        <!-- <mesh filename="package://scout_description/meshes/wheel.dae"/> -->
        <cylinder radius="0.08" length="0.08"/>
      </geometry>
    </collision>
  </link>
  <joint name="rear_right_wheel" type="continuous">

    <parent link="base_link"/>
    <child link="rear_right_wheel_link"/>
    <origin rpy="1.57 0 0" xyz="-0.2319755 -0.2082515 -0.099998"/>
    <axis rpy="0 0 0" xyz="0 0 -1"/>
  </joint>
 
</robot>
