<?xml version="1.0"?>
<robot name="pika2_gripper">
    
    <link name="gripper_base_link">
        <inertial>
            <origin
                xyz="0.037477 -8.1437E-07 0.0084053"
                rpy="0 0 0" />
            <mass
                value="0.18972" />
            <inertia
                ixx="0.0002159"
                ixy="3.3333E-08"
                ixz="-2.6278E-06"
                iyy="0.00014308"
                iyz="1.6782E-08"
                izz="0.00011036" />
            </inertial>
        <visual>
            <origin
                xyz="0 0 0"
                rpy="0 0 0" />
            <geometry>
                <mesh filename="package://agx_arm_description/meshes/pika_gripper_base.dae"/>
            </geometry>
        </visual>
        <collision>
            <origin
                xyz="0 0 0"
                rpy="0 0 0" />
            <geometry>
                <mesh filename="package://agx_arm_description/meshes/pika_gripper_base.dae"/>
            </geometry>
        </collision>
    </link>

    <link name="gripper_left_link">
        <inertial>
        <origin
            xyz="0.033255 -0.014661 -0.0057614"
            rpy="0 0 0" />
        <mass
            value="0.033674" />
        <inertia
            ixx="1.5284E-05"
            ixy="1.4473E-05"
            ixz="1.4911E-08"
            iyy="3.448E-05"
            iyz="-4.3614E-09"
            izz="3.9744E-05" />
        </inertial>
        <visual>
            <origin
                xyz="0 0 0"
                rpy="-1.57 0 1.57" />
            <geometry>
                <mesh filename="package://agx_arm_description/meshes/gripper_left_link.dae"/>
            </geometry>
        </visual>
        <collision>
            <origin
                xyz="0 0 0"
                rpy="-1.57 0 1.57" />
            <geometry>
                <mesh filename="package://agx_arm_description/meshes/gripper_left_link.dae"/>
            </geometry>
        </collision>
    </link>

    <joint name="left_joint" type="prismatic">
        <origin xyz="0.0 0.041 0.08" rpy="1.57 0.0 0.0"/>
        <parent link="gripper_base_link"/>
        <child link="gripper_left_link"/>
        <axis xyz="0.0 0 -1"/>
        <limit effort="100" lower="0.0" upper="0.05" velocity="1"/>
    </joint>

    <link name="gripper_right_link">
        <inertial>
        <origin
            xyz="0.033255 0.014661 -0.0058113"
            rpy="0 0 0" />
        <mass
            value="0.033674" />
        <inertia
            ixx="1.5284E-05"
            ixy="-1.4473E-05"
            ixz="-1.4956E-08"
            iyy="3.448E-05"
            iyz="-4.3614E-09"
            izz="3.9744E-05" />
        </inertial>
        <visual>
            <origin
                xyz="0 0 0"
                rpy="1.57 0 -1.57" />
            <geometry>
                <mesh filename="package://agx_arm_description/meshes/gripper_right_link.dae"/>
            </geometry>
        </visual>
        <collision>
            <origin
                xyz="0 0 0"
                rpy="1.57 0 -1.57" />
            <geometry>
                <mesh filename="package://agx_arm_description/meshes/gripper_right_link.dae"/>
            </geometry>
        </collision>
    </link>

    <joint name="right_joint" type="prismatic">
        <origin xyz="0.0 -0.041 0.08" rpy="-1.57 0.0 0.0"/>
        <parent link="gripper_base_link"/>
        <child link="gripper_right_link"/>
        <axis xyz="0.0 0 1"/>
        <limit effort="100" lower="-0.05" upper="0" velocity="1"/>
    </joint>
</robot>