<?xml version="1.0" ?>
<!-- =================================================================================== -->
<!-- |    This document was autogenerated by xacro from urdf/agx_arm_description.urdf.xacro | -->
<!-- |    EDITING THIS FILE BY HAND IS NOT RECOMMENDED                                 | -->
<!-- =================================================================================== -->
<!--
  agx_arm_description.urdf.xacro
  ================================
  AgileX 系列机械臂统一入口 Xacro 文件。
  通过 arm_type 和 end_effector 两个参数路由到对应的子 URDF/Xacro 文件。

  参数说明:
    arm_type          : piper | piper_h | piper_l | piper_x | nero | revo2
                        默认: piper
    end_effector      : none | gripper | revo2_left | revo2_right
                        默认: none
                        （当 arm_type=revo2 时此参数无效，改用 revo2_side）
    revo2_side        : left | right
                        默认: right
                        （仅当 arm_type=revo2 时生效）
    with_camera_stand : true | false
                        默认: false，是否加载相机支架（固定挂在 gripper_base 上）
    with_camera       : true | false
                        默认: false，是否加载 RealSense D435 相机
                        注意：with_camera:=true 时必须同时设置 with_camera_stand:=true，
                        相机的 d435_camera_link 挂在 camera_stand_link 顶端

  使用示例（命令行直接解析）:
    xacro agx_arm_description.urdf.xacro arm_type:=piper end_effector:=gripper
    xacro agx_arm_description.urdf.xacro arm_type:=piper with_camera_stand:=true with_camera:=true
    xacro agx_arm_description.urdf.xacro arm_type:=nero end_effector:=revo2_right
    xacro agx_arm_description.urdf.xacro arm_type:=revo2 revo2_side:=left
-->
<robot name="agx_arm">
  <link name="world"/>
  <joint name="world_to_base_link" type="fixed">
    <parent link="world"/>
    <child link="base_link"/>
    <origin rpy="0 0 0" xyz="0 0 0"/>
  </joint>
  <link name="base_link">
    <inertial>
      <origin rpy="0 0 0" xyz="-0.00473641164191482 2.56829134630247E-05 0.041451518036016"/>
      <mass value="1.02"/>
      <inertia ixx="0.00267433" ixy="-0.00000073" ixz="-0.00017389" iyy="0.00282612" iyz="0.0000004" izz="0.00089624"/>
    </inertial>
    <visual>
      <origin rpy="0 0 0" xyz="0 0 0"/>
      <geometry>
        <mesh filename="package://agx_arm_description/agx_arm_urdf/piper_l/meshes/dae/base_link.dae"/>
      </geometry>
    </visual>
    <collision>
      <origin rpy="0 0 0" xyz="0 0 0"/>
      <geometry>
        <mesh filename="package://agx_arm_description/agx_arm_urdf/piper_l/meshes/base_link.stl"/>
      </geometry>
    </collision>
  </link>
  <link name="link1">
    <inertial>
      <origin rpy="0 0 0" xyz="0.00032 -0.00041 -0.00348"/>
      <mass value="0.71"/>
      <inertia ixx="0.00050027" ixy="0.00000078" ixz="0.00000626" iyy="0.00040879" iyz="0.00000462" izz="0.00045802"/>
    </inertial>
    <visual>
      <origin rpy="0 0 0" xyz="0 0 0"/>
      <geometry>
        <mesh filename="package://agx_arm_description/agx_arm_urdf/piper_l/meshes/dae/link1.dae"/>
      </geometry>
    </visual>
    <collision>
      <origin rpy="0 0 0" xyz="0 0 0"/>
      <geometry>
        <mesh filename="package://agx_arm_description/agx_arm_urdf/piper_l/meshes/link1.stl"/>
      </geometry>
    </collision>
  </link>
  <joint name="joint1" type="revolute">
    <origin rpy="0 0 0" xyz="0 0 0.123"/>
    <parent link="base_link"/>
    <child link="link1"/>
    <axis xyz="0 0 1"/>
    <limit effort="100" lower="-2.6179938" upper="2.6179938" velocity="5"/>
  </joint>
  <link name="link2">
    <inertial>
      <origin rpy="0 0 0" xyz="0.25852 -0.00861 0.00126"/>
      <mass value="1.16"/>
      <inertia ixx="0.00111915" ixy="0.00182916" ixz="0.00019233" iyy="0.06763251" iyz="0.00000767" izz="0.067559"/>
    </inertial>
    <visual>
      <origin rpy="0 0 0" xyz="0 0 0"/>
      <geometry>
        <mesh filename="package://agx_arm_description/agx_arm_urdf/piper_l/meshes/dae/link2.dae"/>
      </geometry>
    </visual>
    <collision>
      <origin rpy="0 0 0" xyz="0 0 0"/>
      <geometry>
        <mesh filename="package://agx_arm_description/agx_arm_urdf/piper_l/meshes/link2.stl"/>
      </geometry>
    </collision>
  </link>
  <joint name="joint2" type="revolute">
    <origin rpy="1.5707963 -0.1357866 -3.1415926" xyz="0 0 0"/>
    <parent link="link1"/>
    <child link="link2"/>
    <axis xyz="0 0 1"/>
    <limit effort="100" lower="0" upper="3.1415926" velocity="5"/>
  </joint>
  <link name="link3">
    <inertial>
      <origin rpy="0 0 0" xyz="-0.01999 -0.20808 -0.00053"/>
      <mass value="0.5"/>
      <inertia ixx="0.01347608" ixy="0.00161034" ixz="0.00000066" iyy="0.00046377" iyz="0.00000162" izz="0.01363321"/>
    </inertial>
    <visual>
      <origin rpy="0 0 0" xyz="0 0 0"/>
      <geometry>
        <mesh filename="package://agx_arm_description/agx_arm_urdf/piper_l/meshes/dae/link3.dae"/>
      </geometry>
    </visual>
    <collision>
      <origin rpy="0 0 0" xyz="0 0 0"/>
      <geometry>
        <mesh filename="package://agx_arm_description/agx_arm_urdf/piper_l/meshes/link3.stl"/>
      </geometry>
    </collision>
  </link>
  <joint name="joint3" type="revolute">
    <origin rpy="0 0 -1.7938494" xyz="0.33823 0 0"/>
    <parent link="link2"/>
    <child link="link3"/>
    <axis xyz="0 0 1"/>
    <limit effort="100" lower="-2.9670597" upper="0" velocity="5"/>
  </joint>
  <link name="link4">
    <inertial>
      <origin rpy="0 0 0" xyz="0.00013 -0.00076 -0.00394"/>
      <mass value="0.38"/>
      <inertia ixx="0.00017844" ixy="0.00000062" ixz="0.00000067" iyy="0.00018914" iyz="0.00000408" izz="0.00014613"/>
    </inertial>
    <visual>
      <origin rpy="0 0 0" xyz="0 0 0"/>
      <geometry>
        <mesh filename="package://agx_arm_description/agx_arm_urdf/piper_l/meshes/dae/link4.dae"/>
      </geometry>
    </visual>
    <collision>
      <origin rpy="0 0 0" xyz="0 0 0"/>
      <geometry>
        <mesh filename="package://agx_arm_description/agx_arm_urdf/piper_l/meshes/link4.stl"/>
      </geometry>
    </collision>
  </link>
  <joint name="joint4" type="revolute">
    <origin rpy="1.5707963 0 0" xyz="-0.02301 -0.32075 0"/>
    <parent link="link3"/>
    <child link="link4"/>
    <axis xyz="0 0 1"/>
    <limit effort="100" lower="-1.7453292" upper="1.7453292" velocity="5"/>
  </joint>
  <link name="link5">
    <inertial>
      <origin rpy="0 0 0" xyz="0.00018 -0.06104 -0.00227"/>
      <mass value="0.39"/>
      <inertia ixx="0.00172318" ixy="0.00000259" ixz="0.00000010" iyy="0.00017936" iyz="0.00000990" izz="0.00171172"/>
    </inertial>
    <visual>
      <origin rpy="0 0 0" xyz="0 0 0"/>
      <geometry>
        <mesh filename="package://agx_arm_description/agx_arm_urdf/piper_l/meshes/dae/link5.dae"/>
      </geometry>
    </visual>
    <collision>
      <origin rpy="0 0 0" xyz="0 0 0"/>
      <geometry>
        <mesh filename="package://agx_arm_description/agx_arm_urdf/piper_l/meshes/link5.stl"/>
      </geometry>
    </collision>
  </link>
  <joint name="joint5" type="revolute">
    <origin rpy="-1.5707963 0 0" xyz="0 0 0"/>
    <parent link="link4"/>
    <child link="link5"/>
    <axis xyz="0 0 1"/>
    <limit effort="100" lower="-1.2217304" upper="1.2217304" velocity="5"/>
  </joint>
  <link name="link6">
    <inertial>
      <origin rpy="0 0 0" xyz="-0.00003 0.00006 -0.002"/>
      <mass value="0.007"/>
      <inertia ixx="0.00152112" ixy="0.00000202" ixz="0.00000261" iyy="0.00138626" iyz="0.00000002" izz="0.00031152"/>
    </inertial>
    <visual>
      <origin rpy="0 0 0" xyz="0 0 0"/>
      <geometry>
        <mesh filename="package://agx_arm_description/agx_arm_urdf/piper_l/meshes/dae/link6.dae"/>
      </geometry>
    </visual>
    <collision>
      <origin rpy="0 0 0" xyz="0 0 0"/>
      <geometry>
        <mesh filename="package://agx_arm_description/agx_arm_urdf/piper_l/meshes/link6.stl"/>
      </geometry>
    </collision>
  </link>
  <joint name="joint6" type="revolute">
    <origin rpy="1.5707963 0 0" xyz="0 -0.091 0"/>
    <parent link="link5"/>
    <child link="link6"/>
    <axis xyz="0 0 1"/>
    <limit effort="100" lower="-2.0943951" upper="2.0943951" velocity="5"/>
  </joint>
  <link name="gripper_base">
    <inertial>
      <origin rpy="0 0 0" xyz="-0.000183807162235591 8.05033155577911E-05 0.0321436689908876"/>
      <mass value="0.45"/>
      <inertia ixx="0.00092934" ixy="0.00000034" ixz="-0.00000738" iyy="0.00071447" iyz="0.00000005" izz="0.00039442"/>
    </inertial>
    <visual>
      <origin rpy="0 0 0" xyz="0 0 0"/>
      <geometry>
        <mesh filename="package://agx_arm_description/agx_arm_urdf/piper_l/meshes/dae/gripper_base.dae"/>
      </geometry>
    </visual>
    <collision>
      <origin rpy="0 0 0" xyz="0 0 0"/>
      <geometry>
        <mesh filename="package://agx_arm_description/agx_arm_urdf/piper_l/meshes/gripper_base.stl"/>
      </geometry>
    </collision>
  </link>
  <joint name="gripper_base_joint" type="fixed">
    <origin rpy="0 0 0" xyz="0 0 0"/>
    <parent link="link6"/>
    <child link="gripper_base"/>
  </joint>
  <link name="gripper_link1">
    <inertial>
      <origin rpy="0 0 0" xyz="0.00065123185041968 -0.0491929869131989 0.00972258769184025"/>
      <mass value="0.025"/>
      <inertia ixx="0.00007371" ixy="-0.00000113" ixz="0.00000021" iyy="0.00000781" iyz="-0.00001372" izz="0.0000747"/>
    </inertial>
    <visual>
      <origin rpy="0 0 0" xyz="0 0 0"/>
      <geometry>
        <mesh filename="package://agx_arm_description/agx_arm_urdf/piper_l/meshes/dae/gripper_link1.dae"/>
      </geometry>
    </visual>
    <collision>
      <origin rpy="0 0 0" xyz="0 0 0"/>
      <geometry>
        <mesh filename="package://agx_arm_description/agx_arm_urdf/piper_l/meshes/gripper_link1.stl"/>
      </geometry>
    </collision>
  </link>
  <joint name="gripper_joint1" type="prismatic">
    <origin rpy="1.5707963 0 0" xyz="0 0 0.1358"/>
    <parent link="gripper_base"/>
    <child link="gripper_link1"/>
    <axis xyz="0 0 1"/>
    <limit effort="10" lower="0" upper="0.05" velocity="3"/>
  </joint>
  <link name="gripper_link2">
    <inertial>
      <origin rpy="0 0 0" xyz="0.00065123185041968 -0.0491929869131989 0.00972258769184025"/>
      <mass value="0.025"/>
      <inertia ixx="0.00007371" ixy="-0.00000113" ixz="0.00000021" iyy="0.00000781" iyz="-0.00001372" izz="0.0000747"/>
    </inertial>
    <visual>
      <origin rpy="0 0 0" xyz="0 0 0"/>
      <geometry>
        <mesh filename="package://agx_arm_description/agx_arm_urdf/piper_l/meshes/dae/gripper_link2.dae"/>
      </geometry>
    </visual>
    <collision>
      <origin rpy="0 0 0" xyz="0 0 0"/>
      <geometry>
        <mesh filename="package://agx_arm_description/agx_arm_urdf/piper_l/meshes/gripper_link2.stl"/>
      </geometry>
    </collision>
  </link>
  <joint name="gripper_joint2" type="prismatic">
    <origin rpy="1.5707963 0 -3.1415926" xyz="0 0 0.1358"/>
    <parent link="gripper_base"/>
    <child link="gripper_link2"/>
    <axis xyz="0 0 -1"/>
    <limit effort="10" lower="-0.05" upper="0" velocity="3"/>
  </joint>
  <link name="camera_stand_link">
    <inertial>
      <origin rpy="0 0 0" xyz="0 0 0"/>
      <mass value="0.2"/>
      <inertia ixx="0.0002" ixy="0.0" ixz="0.0" iyy="0.0002" iyz="0.0" izz="0.0001"/>
    </inertial>
    <visual>
      <origin rpy="-1.57 0 1.57" xyz="0 0 0"/>
      <geometry>
        <mesh filename="package://agx_arm_description/meshes/realsense_mid_stand.dae"/>
      </geometry>
    </visual>
    <collision>
      <origin rpy="0 0 0" xyz="0 0 0"/>
      <geometry>
        <mesh filename="package://agx_arm_description/meshes/realsense_mid_stand.dae"/>
      </geometry>
    </collision>
  </link>
  <joint name="camera_stand_joint" type="fixed">
    <origin rpy="0.0 0.0 0.0" xyz="-0.034 -0.001 0.022"/>
    <parent link="gripper_base"/>
    <child link="camera_stand_link"/>
  </joint>
  <material name="aluminum">
    <color rgba="0.5 0.5 0.5 1"/>
  </material>
  <material name="plastic">
    <color rgba="0.1 0.1 0.1 1"/>
  </material>
  <link name="d435_camera_link"/>
  <!-- camera body, with origin at bottom screw mount -->
  <joint name="camera_joint" type="fixed">
    <origin rpy="0 0 0" xyz="0 0 0"/>
    <parent link="d435_camera_link"/>
    <child link="camera_bottom_screw_frame"/>
  </joint>
  <link name="camera_bottom_screw_frame"/>
  <joint name="camera_link_joint" type="fixed">
    <origin rpy="0 0 0" xyz="0.010600000000000002 0.0175 0.0125"/>
    <parent link="camera_bottom_screw_frame"/>
    <child link="camera_link"/>
  </joint>
  <link name="camera_link">
    <visual>
      <!-- the mesh origin is at front plate in between the two infrared camera axes -->
      <origin rpy="1.5707963267948966 0 1.5707963267948966" xyz="0.0043 -0.0175 0"/>
      <geometry>
        <mesh filename="package://realsense2_description/meshes/d435.dae"/>
      </geometry>
    </visual>
    <collision>
      <origin rpy="0 0 0" xyz="0 -0.0175 0"/>
      <geometry>
        <box size="0.02505 0.09 0.025"/>
      </geometry>
    </collision>
    <inertial>
      <!-- The following are not reliable values, and should not be used for modeling -->
      <mass value="0.072"/>
      <origin xyz="0 0 0"/>
      <inertia ixx="0.003881243" ixy="0.0" ixz="0.0" iyy="0.000498940" iyz="0.0" izz="0.003879257"/>
    </inertial>
  </link>
  <!-- <xacro:if value="${add_plug}">
      <xacro:usb_plug parent="${name}_link" name="${name}_usb_plug">
        <origin xyz="${d435_cam_mount_from_center_offset - 0.02095} ${-d435_cam_depth_py - 0.0353} 0" rpy="0 0 0"/>
      </xacro:usb_plug>
    </xacro:if> -->
  <joint name="d435_camera_joint" type="fixed">
    <origin rpy="0.0 -1.22 0.0" xyz="-0.031 -0.028 0.0018"/>
    <parent link="camera_stand_link"/>
    <child link="d435_camera_link"/>
  </joint>
</robot>
